Workbook

Sheet summary
A1: VINTAGE | B1: sec79 | C1: sec95 | D1: chainindex | E1: new browser | F1: base | G1: units | H1: d1980 | I1: d1985 | J1: d1990 | K1: d1995 | L1: d1995e | M1: d2000ec | N1: d2010ec | O1: d2015ec | P1: d2020ec
A2: 1 | B2: V882 | F2: 1980 | G2: mld lire | H2: 1 | I2: 0 | J2: 0 | K2: 0 | L2: 0 | M2: 0 | N2: 0 | O2: 0 | P2: 0
A3: =1+A2 -> 2 | B3: V883 | F3: 1980 | G3: mld lire | H3: 1 | I3: 0 | J3: 0 | K3: 0 | L3: 0 | M3: 0 | N3: 0 | O3: 0 | P3: 0
A4: =1+A3 -> 3 | B4: V884 | F4: 1980 | G4: mld lire | H4: 1 | I4: 0 | J4: 0 | K4: 0 | L4: 0 | M4: 0 | N4: 0 | O4: 0 | P4: 0
A5: =1+A4 -> 4 | B5: V891 | F5: 1980 | G5: mld lire | H5: 1 | I5: 0 | J5: 0 | K5: 0 | L5: 0 | M5: 0 | N5: 0 | O5: 0 | P5: 0
A6: =1+A5 -> 5 | B6: V892 | F6: 1980 | G6: mld lire | H6: 1 | I6: 0 | J6: 0 | K6: 0 | L6: 0 | M6: 0 | N6: 0 | O6: 0 | P6: 0
A7: =1+A6 -> 6 | B7: V893 | F7: 1980 | G7: mld lire | H7: 1 | I7: 0 | J7: 0 | K7: 0 | L7: 0 | M7: 0 | N7: 0 | O7: 0 | P7: 0
A8: =1+A7 -> 7 | B8: V894 | F8: 1980 | G8: mld lire | H8: 1 | I8: 0 | J8: 0 | K8: 0 | L8: 0 | M8: 0 | N8: 0 | O8: 0 | P8: 0
A9: =1+A8 -> 8 | B9: V901 | F9: 1980 | G9: mld lire | H9: 1 | I9: 0 | J9: 0 | K9: 0 | L9: 0 | M9: 0 | N9: 0 | O9: 0 | P9: 0
A10: =1+A9 -> 9 | B10: V902 | F10: 1980 | G10: mld lire | H10: 1 | I10: 0 | J10: 0 | K10: 0 | L10: 0 | M10: 0 | N10: 0 | O10: 0 | P10: 0
A11: =1+A10 -> 10 | B11: V903 | F11: 1980 | G11: mld lire | H11: 1 | I11: 0 | J11: 0 | K11: 0 | L11: 0 | M11: 0 | N11: 0 | O11: 0 | P11: 0
A12: =1+A11 -> 11 | B12: V904 | F12: 1980 | G12: mld lire | H12: 1 | I12: 0 | J12: 0 | K12: 0 | L12: 0 | M12: 0 | N12: 0 | O12: 0 | P12: 0
A13: =1+A12 -> 12 | B13: V911 | F13: 1985 | G13: mld lire | H13: 0 | I13: 1 | J13: 0 | K13: 0 | L13: 0 | M13: 0 | N13: 0 | O13: 0 | P13: 0
A14: =1+A13 -> 13 | B14: V912 | F14: 1985 | G14: mld lire | H14: 0 | I14: 1 | J14: 0 | K14: 0 | L14: 0 | M14: 0 | N14: 0 | O14: 0 | P14: 0
... A36: =1+A35 -> 35 | B36: V964 | F36: 1990 | G36: mld lire | H36: 0 | I36: 0 | J36: 1 | K36: 0 | L36: 0 | M36: 0 | N36: 0 | O36: 0 | P36: 0
A37: =1+A36 -> 36 | B37: V971 | C37: PIL971 | F37: 1990 | G37: mld lire | H37: 0 | I37: 0 | J37: 1 | K37: 0 | L37: 0 | M37: 0 | N37: 0 | O37: 0 | P37: 0
A38: =1+A37 -> 37 | B38: V972 | C38: PIL972 | F38: 1990 | G38: mld lire | H38: 0 | I38: 0 | J38: 1 | K38: 0 | L38: 0 | M38: 0 | N38: 0 | O38: 0 | P38: 0
A39: =1+A38 -> 38 | B39: V973 | C39: PIL973 | F39: 1990 | G39: mld lire | H39: 0 | I39: 0 | J39: 1 | K39: 0 | L39: 0 | M39: 0 | N39: 0 | O39: 0 | P39: 0
A40: =1+A39 -> 39 | B40: V974 | C40: PIL974 | F40: 1990 | G40: mld lire | H40: 0 | I40: 0 | J40: 1 | K40: 0 | L40: 0 | M40: 0 | N40: 0 | O40: 0 | P40: 0
A41: =1+A40 -> 40 | B41: V981 | C41: PIL981 | F41: 1990 | G41: mld lire | H41: 0 | I41: 0 | J41: 1 | K41: 0 | L41: 0 | M41: 0 | N41: 0 | O41: 0 | P41: 0
A42: =1+A41 -> 41 | B42: V982 | C42: PIL982 | F42: 1990 | G42: mld lire | H42: 0 | I42: 0 | J42: 1 | K42: 0 | L42: 0 | M42: 0 | N42: 0 | O42: 0 | P42: 0
A43: =1+A42 -> 42 | B43: V983 | C43: PIL983 | F43: 1990 | G43: mld lire | H43: 0 | I43: 0 | J43: 1 | K43: 0 | L43: 0 | M43: 0 | N43: 0 | O43: 0 | P43: 0
A44: =1+A43 -> 43 | C44: PIL984 | F44: 1995 | G44: mld lire | H44: 0 | I44: 0 | J44: 0 | K44: 1 | L44: 0 | M44: 0 | N44: 0 | O44: 0 | P44: 0
A45: =1+A44 -> 44 | C45: PIL991 | F45: 1995 | G45: mld lire | H45: 0 | I45: 0 | J45: 0 | K45: 1 | L45: 0 | M45: 0 | N45: 0 | O45: 0 | P45: 0
A46: =1+A45 -> 45 | C46: PIL992 | F46: 1995 | G46: mld lire | H46: 0 | I46: 0 | J46: 0 | K46: 1 | L46: 0 | M46: 0 | N46: 0 | O46: 0 | P46: 0
A47: =1+A46 -> 46 | C47: PIL993 | F47: 1995 | G47: mld lire | H47: 0 | I47: 0 | J47: 0 | K47: 1 | L47: 0 | M47: 0 | N47: 0 | O47: 0 | P47: 0
A48: =1+A47 -> 47 | C48: PIL994 | F48: 1995 | G48: mld lire | H48: 0 | I48: 0 | J48: 0 | K48: 1 | L48: 0 | M48: 0 | N48: 0 | O48: 0 | P48: 0
A49: =1+A48 -> 48 | C49: PIL001 | F49: 1995 | G49: mld lire | H49: 0 | I49: 0 | J49: 0 | K49: 1 | L49: 0 | M49: 0 | N49: 0 | O49: 0 | P49: 0
A50: =1+A49 -> 49 | C50: PIL002 | F50: 1995 | G50: mld lire | H50: 0 | I50: 0 | J50: 0 | K50: 1 | L50: 0 | M50: 0 | N50: 0 | O50: 0 | P50: 0
A51: =1+A50 -> 50 | C51: PIL003 | F51: 1995 | G51: mld lire | H51: 0 | I51: 0 | J51: 0 | K51: 1 | L51: 0 | M51: 0 | N51: 0 | O51: 0 | P51: 0
A52: =1+A51 -> 51 | C52: PIL004 | F52: 1995 | G52: mld lire | H52: 0 | I52: 0 | J52: 0 | K52: 1 | L52: 0 | M52: 0 | N52: 0 | O52: 0 | P52: 0
A53: =1+A52 -> 52 | C53: PIL011 | F53: 1995 | G53: mld lire | H53: 0 | I53: 0 | J53: 0 | K53: 1 | L53: 0 | M53: 0 | N53: 0 | O53: 0 | P53: 0
A54: =1+A53 -> 53 | C54: PIL012 | F54: 1995 | G54: mld lire | H54: 0 | I54: 0 | J54: 0 | K54: 1 | L54: 0 | M54: 0 | N54: 0 | O54: 0 | P54: 0
A55: =1+A54 -> 54 | C55: PIL013 | F55: 1995 | G55: mld lire | H55: 0 | I55: 0 | J55: 0 | K55: 1 | L55: 0 | M55: 0 | N55: 0 | O55: 0 | P55: 0
... A71: =1+A70 -> 70 | C71: PIL053 | F71: 1995 | G71: mln euro | H71: 0 | I71: 0 | J71: 0 | K71: 0 | L71: 1 | M71: 0 | N71: 0 | O71: 0 | P71: 0
A72: =1+A71 -> 71 | D72: GDP054 | F72: ci_2000 | G72: mln euro | H72: 0 | I72: 0 | J72: 0 | K72: 0 | L72: 0 | M72: 1 | N72: 0 | O72: 0 | P72: 0
A73: =1+A72 -> 72 | D73: GDP061 | F73: ci_2000 | G73: mln euro | H73: 0 | I73: 0 | J73: 0 | K73: 0 | L73: 0 | M73: 1 | N73: 0 | O73: 0 | P73: 0
A74: =1+A73 -> 73 | D74: GDP062 | F74: ci_2000 | G74: mln euro | H74: 0 | I74: 0 | J74: 0 | K74: 0 | L74: 0 | M74: 1 | N74: 0 | O74: 0 | P74: 0
A75: =1+A74 -> 74 | D75: GDP063 | F75: ci_2000 | G75: mln euro | H75: 0 | I75: 0 | J75: 0 | K75: 0 | L75: 0 | M75: 1 | N75: 0 | O75: 0 | P75: 0
A76: =1+A75 -> 75 | D76: GDP064 | F76: ci_2000 | G76: mln euro | H76: 0 | I76: 0 | J76: 0 | K76: 0 | L76: 0 | M76: 1 | N76: 0 | O76: 0 | P76: 0
...

Sheet sec79
A1: DATE | B1: V882 | C1: V883 | D1: V884 | E1: V891 | F1: V892 | G1: V893 | H1: V894 | I1: V901 | J1: V902 | K1: V903 | L1: V904 | M1: V911 | N1: V912 | O1: V913 | P1: V914 | Q1: V921 | R1: V922 | S1: V923 | T1: V924 | U1: V931 | V1: V932 | W1: V933 | X1: V934 | Y1: V941 | Z1: V942 | AA1: V943 | AB1: V944 | AC1: V951 | AD1: V952 | AE1: V953 | AF1: V954 | AG1: V961 | AH1: V962 | AI1: V963 | AJ1: V964 | AK1: V971 | AL1: V972 | AM1: V973 | AN1: V974 | AO1: V981 | AP1: V982 | AQ1: V983
B2: y1 | C2: y2 | D2: y3 | E2: y4 | F2: y5 | G2: y6 | H2: y7 | I2: y8 | J2: y9 | K2: y10 | L2: y11 | M2: y12 | N2: y13 | O2: y14 | P2: y15 | Q2: y16 | R2: y17 | S2: y18 | T2: y19 | U2: y20 | V2: y21 | W2: y22 | X2: y23 | Y2: y24 | Z2: y25 | AA2: y26 | AB2: y27 | AC2: y28 | AD2: y29 | AE2: y30 | AF2: y31 | AG2: y32 | AH2: y33 | AI2: y34 | AJ2: y35
A3: 1970.1 | B3: 65950 | C3: =0.9916*(B3+D3)/2 -> 65421.306 | D3: 66001 | E3: 66209 | F3: =E3 -> 66209 | G3: =F3 -> 66209 | H3: 66209 | I3: 66209 | J3: 66209 | K3: 66209 | L3: =K3 -> 66209 | M3: 129544 | N3: =M3 -> 129544 | O3: 129544 | P3: 129544 | Q3: 129544 | R3: 129424 | S3: 129424 | T3: 129424 | U3: =T3 -> 129424 | V3: 129424 | W3: 129424 | X3: 129424 | Y3: 129424 | Z3: 129424 | AA3: 129424 | AB3: 129424 | AC3: 129424 | AD3: 129424 | AE3: 129424 | AF3: 181584 | AG3: 181584 | AH3: 181584 | AI3: 181584 | AJ3: 181584 | AK3: 181584 | AL3: 181584 | AM3: 181584 | AN3: 181584 | AO3: 181584 | AP3: 181584 | AQ3: 181584
A4: 1970.2 | B4: 66761 | C4: =0.9916*(B4+D4)/2 -> 66201.695 | D4: 66764 | E4: 66532 | F4: =E4 -> 66532 | G4: =F4 -> 66532 | H4: 66532 | I4: 66532 | J4: 66532 | K4: 66532 | L4: =K4 -> 66532 | M4: 130180 | N4: =M4 -> 130180 | O4: 130180 | P4: 130180 | Q4: 130180 | R4: 130479 | S4: 130479 | T4: 130479 | U4: =T4 -> 130479 | V4: 130479 | W4: 130479 | X4: 130479 | Y4: 130479 | Z4: 130479 | AA4: 130479 | AB4: 130479 | AC4: 130479 | AD4: 130479 | AE4: 130479 | AF4: 183654 | AG4: 183671 | AH4: 184060 | AI4: 184060 | AJ4: 184060 | AK4: 184060 | AL4: 184060 | AM4: 184060 | AN4: 184060 | AO4: 184060 | AP4: 184060 | AQ4: 184060
A5: 1970.3 | B5: 68060 | C5: =0.9916*(B5+D5)/2 -> 67466.481 | D5: 68016 | E5: 67465 | F5: =E5 -> 67465 | G5: =F5 -> 67465 | H5: 67465 | I5: 67465 | J5: 67465 | K5: 67465 | L5: =K5 -> 67465 | M5: 132380 | N5: =M5 -> 132380 | O5: 132380 | P5: 132380 | Q5: 132380 | R5: 132317 | S5: 132317 | T5: 132317 | U5: =T5 -> 132317 | V5: 132317 | W5: 132317 | X5: 132317 | Y5: 132317 | Z5: 132317 | AA5: 132317 | AB5: 132317 | AC5: 132317 | AD5: 132317 | AE5: 132317 | AF5: 187333 | AG5: 187319 | AH5: 186705 | AI5: 186705 | AJ5: 186705 | AK5: 186705 | AL5: 186705 | AM5: 186705 | AN5: 186705 | AO5: 186705 | AP5: 186705 | AQ5: 186705
A6: 1970.4 | B6: 67024 | C6: =0.9916*(B6+D6)/2 -> 66455.545 | D6: 67013 | E6: 67588 | F6: =E6 -> 67588 | G6: =F6 -> 67588 | H6: 67588 | I6: 67588 | J6: 67588 | K6: 67588 | L6: =K6 -> 67588 | M6: 132808 | N6: =M6 -> 132808 | O6: 132808 | P6: 132808 | Q6: 132808 | R6: 132605 | S6: 132605 | T6: 132605 | U6: =T6 -> 132605 | V6: 132605 | W6: 132605 | X6: 132605 | Y6: 132605 | Z6: 132605 | AA6: 132605 | AB6: 132605 | AC6: 132605 | AD6: 132605 | AE6: 132605 | AF6: 187153 | AG6: 187023 | AH6: 186066 | AI6: 186066 | AJ6: 186066 | AK6: 186066 | AL6: 186066 | AM6: 186066 | AN6: 186066 | AO6: 186066 | AP6: 186066 | AQ6: 186066
A7: 1971.1 | B7: 67094 | C7: =0.9916*(B7+D7)/2 -> 66533.881 | D7: 67101 | E7: 67654 | F7: =E7 -> 67654 | G7: =F7 -> 67654 | H7: 67654 | I7: 67654 | J7: 67654 | K7: 67654 | L7: =K7 -> 67654 | M7: 132751 | N7: =M7 -> 132751 | O7: 132918 | P7: 132918 | Q7: 132918 | R7: 132578 | S7: 132589 | T7: 132589 | U7: =T7 -> 132589 | V7: 132589 | W7: 132589 | X7: 132589 | Y7: 132589 | Z7: 132589 | AA7: 132589 | AB7: 132589 | AC7: 132589 | AD7: 132589 | AE7: 132589 | AF7: 187184 | AG7: 186873 | AH7: 186657 | AI7: 186657 | AJ7: 186657 | AK7: 186657 | AL7: 186657 | AM7: 186657 | AN7: 186657 | AO7: 186657 | AP7: 186657 | AQ7: 186657
A8: 1971.2 | B8: 67382 | C8: =0.9916*(B8+D8)/2 -> 66822.932 | D8: 67396 | E8: 67472 | F8: =E8 -> 67472 | G8: =F8 -> 67472 | H8: 67472 | I8: 67472 | J8: 67472 | K8: 67472 | L8: =K8 -> 67472 | M8: 132463 | N8: =M8 -> 132463 | O8: 132414 | P8: 132414 | Q8: 132414 | R8: 132571 | S8: 132558 | T8: 132558 | U8: =T8 -> 132558 | V8: 132558 | W8: 132558 | X8: 132558 | Y8: 132558 | Z8: 132558 | AA8: 132558 | AB8: 132558 | AC8: 132558 | AD8: 132558 | AE8: 132558 | AF8: 186623 | AG8: 186650 | AH8: 186728 | AI8: 186728 | AJ8: 186728 | AK8: 186728 | AL8: 186728 | AM8: 186728 | AN8: 186728 | AO8: 186728 | AP8: 186728 | AQ8: 186728
A9: 1971.3 | B9: 68305 | C9: =0.9916*(B9+D9)/2 -> 67731.238 | D9: 68305 | E9: 68096 | F9: =E9 -> 68096 | G9: =F9 -> 68096 | H9: 68096 | I9: 68096 | J9: 68096 | K9: 68096 | L9: =K9 -> 68096 | M9: 133762 | N9: =M9 -> 133762 | O9: 133686 | P9: 133686 | Q9: 133686 | R9: 133711 | S9: 133712 | T9: 133712 | U9: =T9 -> 133712 | V9: 133712 | W9: 133712 | X9: 133712 | Y9: 133712 | Z9: 133712 | AA9: 133712 | AB9: 133712 | AC9: 133712 | AD9: 133712 | AE9: 133712 | AF9: 188255 | AG9: 188367 | AH9: 188689 | AI9: 188689 | AJ9: 188689 | AK9: 188689 | AL9: 188689 | AM9: 188689 | AN9: 188689 | AO9: 188689 | AP9: 188689 | AQ9: 188689
A10: 1971.4 | B10: 69311 | C10: =0.9916*(B10+D10)/2 -> 68718.376 | D10: 69290 | E10: 68870 | F10: =E10 -> 68870 | G10: =F10 -> 68870 | H10: 68870 | I10: 68870 | J10: 68870 | K10: 68870 | L10: =K10 -> 68870 | M10: 135131 | N10: =M10 -> 135131 | O10: 135090 | P10: 135090 | Q10: 135090 | R10: 135210 | S10: 135212 | T10: 135212 | U10: =T10 -> 135212 | V10: 135212 | W10: 135212 | X10: 135212 | Y10: 135212 | Z10: 135212 | AA10: 135212 | AB10: 135212 | AC10: 135212 | AD10: 135212 | AE10: 135212 | AF10: 190340 | AG10: 190512 | AH10: 190328 | AI10: 190328 | AJ10: 190328 | AK10: 190328 | AL10: 190328 | AM10: 190328 | AN10: 190328 | AO10: 190328 | AP10: 190328 | AQ10: 190328
A11: 1972.1 | B11: 70012 | C11: =0.9916*(B11+D11)/2 -> 69407.042 | D11: 69978 | E11: 69737 | F11: =E11 -> 69737 | G11: =F11 -> 69737 | H11: 69737 | I11: 69737 | J11: 69737 | K11: 69737 | L11: =K11 -> 69737 | M11: 136887 | N11: =M11 -> 136887 | O11: 136774 | P11: 136774 | Q11: 136774 | R11: 136925 | S11: 136921 | T11: 136921 | U11: =T11 -> 136921 | V11: 136921 | W11: 136921 | X11: 136921 | Y11: 136921 | Z11: 136921 | AA11: 136921 | AB11: 136921 | AC11: 136921 | AD11: 136921 | AE11: 136921 | AF11: 193026 | AG11: 192803 | AH11: 192961 | AI11: 192961 | AJ11: 192961 | AK11: 192961 | AL11: 192961 | AM11: 192961 | AN11: 192961 | AO11: 192961 | AP11: 192961 | AQ11: 192961
A12: 1972.2 | B12: 68799 | C12: =0.9916*(B12+D12)/2 -> 68228.525 | D12: 68814 | E12: 69066 | F12: =E12 -> 69066 | G12: =F12 -> 69066 | H12: 69066 | I12: 69066 | J12: 69066 | K12: 69066 | L12: =K12 -> 69066 | M12: 135748 | N12: =M12 -> 135748 | O12: 135779 | P12: 135779 | Q12: 135779 | R12: 135609 | S12: 135618 | T12: 135618 | U12: =T12 -> 135618 | V12: 135618 | W12: 135618 | X12: 135618 | Y12: 135618 | Z12: 135618 | AA12: 135618 | AB12: 135618 | AC12: 135618 | AD12: 135618 | AE12: 135618 | AF12: 191651 | AG12: 191947 | AH12: 192295 | AI12: 192295 | AJ12: 192295 | AK12: 192295 | AL12: 192295 | AM12: 192295 | AN12: 192295 | AO12: 192295 | AP12: 192295 | AQ12: 192295
A13: 1972.3 | B13: 69250 | C13: =0.9916*(B13+D13)/2 -> 68680.695 | D13: 69275 | E13: 69766 | F13: =E13 -> 69766 | G13: =F13 -> 69766 | H13: 69766 | I13: 69766 | J13: 69766 | K13: 69766 | L13: =K13 -> 69766 | M13: 137352 | N13: =M13 -> 137352 | O13: 137388 | P13: 137388 | Q13: 137388 | R13: 137206 | S13: 137217 | T13: 137217 | U13: =T13 -> 137217 | V13: 137217 | W13: 137217 | X13: 137217 | Y13: 137217 | Z13: 137217 | AA13: 137217 | AB13: 137217 | AC13: 137217 | AD13: 137217 | AE13: 137217 | AF13: 193755 | AG13: 193436 | AH13: 193616 | AI13: 193616 | AJ13: 193616 | AK13: 193616 | AL13: 193616 | AM13: 193616 | AN13: 193616 | AO13: 193616 | AP13: 193616 | AQ13: 193616
A14: 1972.4 | B14: 71375 | C14: =0.9916*(B14+D14)/2 -> 70772.971 | D14: 71370 | E14: 70868 | F14: =E14 -> 70868 | G14: =F14 -> 70868 | H14: 70868 | I14: 70868 | J14: 70868 | K14: 70868 | L14: =K14 -> 70868 | M14: 139205 | N14: =M14 -> 139205 | O14: 139251 | P14: 139251 | Q14: 139251 | R14: 139208 | S14: 139192 | T14: 139192 | U14: =T14 -> 139192 | V14: 139192 | W14: 139192 | X14: 139192 | Y14: 139192 | Z14: 139192 | AA14: 139192 | AB14: 139192 | AC14: 139192 | AD14: 139192 | AE14: 139192 | AF14: 195986 | AG14: 196232 | AH14: 195546 | AI14: 195546 | AJ14: 195546 | AK14: 195546 | AL14: 195546 | AM14: 195546 | AN14: 195546 | AO14: 195546 | AP14: 195546 | AQ14: 195546
... A74: 1987.4 | B74: 113640 | C74: =0.9916*(B74+D74)/2 -> 111869.83 | D74: 111995 | E74: 112869 | F74: =E74 -> 112869 | G74: =F74 -> 112869 | H74: 112869 | I74: 112869 | J74: 112869 | K74: 112869 | L74: =K74 -> 112869 | M74: 218979 | N74: =M74 -> 218979 | O74: 218789 | P74: 218852 | Q74: 218852 | R74: 218376 | S74: 218376 | T74: 218376 | U74: =T74 -> 218376 | V74: 218376 | W74: 218376 | X74: 218376 | Y74: 218376 | Z74: 218376 | AA74: 218376 | AB74: 218376 | AC74: 218376 | AD74: 218376 | AE74: 218376 | AF74: 305269 | AG74: 305314 | AH74: 305082 | AI74: 305082 | AJ74: 305082 | AK74: 305082 | AL74: 305082 | AM74: 305082 | AN74: 305082 | AO74: 305082 | AP74: 305082 | AQ74: 305082
A75: 1988.1 | B75: 115061 | C75: 113382 | D75: 113615 | E75: 113997 | F75: =E75 -> 113997 | G75: 113965 | H75: 114112 | I75: 114111 | J75: 114113 | K75: 114280 | L75: =K75 -> 114280 | M75: 221150 | N75: =M75 -> 221150 | O75: 221139 | P75: 221429 | Q75: 221429 | R75: 221373 | S75: 221373 | T75: 221172 | U75: =T75 -> 221172 | V75: 221172 | W75: 221172 | X75: 221172 | Y75: 221172 | Z75: 221172 | AA75: 221172 | AB75: 221172 | AC75: 221172 | AD75: 221172 | AE75: 221172 | AF75: 309675 | AG75: 308693 | AH75: 308723 | AI75: 308723 | AJ75: 308723 | AK75: 308723 | AL75: 308723 | AM75: 308723 | AN75: 308723 | AO75: 308723 | AP75: 308723 | AQ75: 308723
A76: 1988.2 | B76: 115793 | C76: 114514 | D76: 114498 | E76: 114615 | F76: =E76 -> 114615 | G76: 114569 | H76: 114888 | I76: 114820 | J76: 114848 | K76: 114928 | L76: =K76 -> 114928 | M76: 223134 | N76: =M76 -> 223134 | O76: 223034 | P76: 223330 | Q76: 223330 | R76: 223232 | S76: 223232 | T76: 223163 | U76: =T76 -> 223163 | V76: 223163 | W76: 223163 | X76: 223163 | Y76: 223163 | Z76: 223163 | AA76: 223163 | AB76: 223163 | AC76: 223163 | AD76: 223163 | AE76: 223163 | AF76: 310393 | AG76: 310187 | AH76: 310305 | AI76: 310305 | AJ76: 310305 | AK76: 310305 | AL76: 310305 | AM76: 310305 | AN76: 310305 | AO76: 310305 | AP76: 310305 | AQ76: 310305
A77: 1988.3 | C77: 115889 | D77: 115716 | E77: 115451 | F77: =E77 -> 115451 | G77: 115550 | H77: 116111 | I77: 116035 | J77: 116017 | K77: 115856 | L77: =K77 -> 115856 | M77: 224702 | N77: =M77 -> 224702 | O77: 224709 | P77: 224621 | Q77: 224621 | R77: 224445 | S77: 224445 | T77: 225077 | U77: =T77 -> 225077 | V77: 225077 | W77: 225077 | X77: 225077 | Y77: 225077 | Z77: 225077 | AA77: 225077 | AB77: 225077 | AC77: 225077 | AD77: 225077 | AE77: 225077 | AF77: 312688 | AG77: 312956 | AH77: 312467 | AI77: 312467 | AJ77: 312467 | AK77: 312467 | AL77: 312467 | AM77: 312467 | AN77: 312467 | AO77: 312467 | AP77: 312467 | AQ77: 312467
A78: 1988.4 | D78: 116888 | E78: 116655 | F78: =E78 -> 116655 | G78: 116463 | H78: 116856 | I78: 117001 | J78: 116989 | K78: 116903 | L78: =K78 -> 116903 | M78: 226411 | N78: =M78 -> 226411 | O78: 226514 | P78: 226017 | Q78: 226017 | R78: 226347 | S78: 226347 | T78: 225985 | U78: =T78 -> 225985 | V78: 225985 | W78: 225985 | X78: 225985 | Y78: 225985 | Z78: 225985 | AA78: 225985 | AB78: 225985 | AC78: 225985 | AD78: 225985 | AE78: 225985 | AF78: 314209 | AG78: 315130 | AH78: 315470 | AI78: 315470 | AJ78: 315470 | AK78: 315470 | AL78: 315470 | AM78: 315470 | AN78: 315470 | AO78: 315470 | AP78: 315470 | AQ78: 315470
A79: 1989.1 | E79: 117513 | F79: =E79 -> 117513 | G79: 117574 | H79: 118014 | I79: 117794 | J79: 117696 | K79: 117855 | L79: =K79 -> 117855 | M79: 227723 | N79: =M79 -> 227723 | O79: 227959 | P79: 227596 | Q79: 227596 | R79: 227661 | S79: 227661 | T79: 227639 | U79: =T79 -> 227639 | V79: 227639 | W79: 227639 | X79: 227860 | Y79: 227860 | Z79: 227860 | AA79: 227860 | AB79: 227860 | AC79: 227860 | AD79: 227860 | AE79: 227860 | AF79: 317513 | AG79: 317731 | AH79: 317377 | AI79: 317377 | AJ79: 317377 | AK79: 317377 | AL79: 317377 | AM79: 317377 | AN79: 317377 | AO79: 317377 | AP79: 317377 | AQ79: 317377
A80: 1989.2 | F80: 118292 | G80: 117990 | H80: 118794 | I80: 118735 | J80: 118721 | K80: 118758 | L80: =K80 -> 118758 | M80: 229849 | N80: =M80 -> 229849 | O80: 229918 | P80: 229725 | Q80: 229725 | R80: 229748 | S80: 229748 | T80: 229084 | U80: =T80 -> 229084 | V80: 229084 | W80: 229084 | X80: 229100 | Y80: 229100 | Z80: 229100 | AA80: 229100 | AB80: 229100 | AC80: 229100 | AD80: 229100 | AE80: 229100 | AF80: 318495 | AG80: 318567 | AH80: 319084 | AI80: 319084 | AJ80: 319084 | AK80: 319084 | AL80: 319084 | AM80: 319084 | AN80: 319084 | AO80: 319084 | AP80: 319084 | AQ80: 319084
A81: 1989.3 | G81: 118929 | H81: 119624 | I81: 119715 | J81: 119651 | K81: 119563 | L81: =K81 -> 119563 | M81: 232081 | N81: =M81 -> 232081 | O81: 231893 | P81: 231704 | Q81: 231704 | R81: 231522 | S81: 231522 | T81: 232231 | U81: =T81 -> 232231 | V81: 232231 | W81: 232231 | X81: 231690 | Y81: 231690 | Z81: 231690 | AA81: 231690 | AB81: 231690 | AC81: 231690 | AD81: 231690 | AE81: 231690 | AF81: 322603 | AG81: 322227 | AH81: 321280 | AI81: 321280 | AJ81: 321280 | AK81: 321280 | AL81: 321280 | AM81: 321280 | AN81: 321280 | AO81: 321280 | AP81: 321280 | AQ81: 321280
A82: 1989.4 | H82: 120146 | I82: 120334 | J82: 120511 | K82: 120402 | L82: =K82 -> 120402 | M82: 232905 | N82: =M82 -> 232905 | O82: 232788 | P82: 232690 | Q82: 232690 | R82: 232784 | S82: 232784 | T82: 232761 | U82: =T82 -> 232761 | V82: 232761 | W82: 232761 | X82: 233064 | Y82: 233064 | Z82: 233064 | AA82: 233064 | AB82: 233064 | AC82: 233064 | AD82: 233064 | AE82: 233064 | AF82: 324294 | AG82: 324380 | AH82: 325165 | AI82: 325165 | AJ82: 325165 | AK82: 325165 | AL82: 325165 | AM82: 325165 | AN82: 325165 | AO82: 325165 | AP82: 325165 | AQ82: 325165
A83: 1990.1 | I83: 121464 | J83: 121263 | K83: 121389 | L83: 121097 | M83: 234859 | N83: 234768.24 | O83: 234521 | P83: 234437 | Q83: 234411 | R83: 234515 | S83: 234539 | T83: 234480 | U83: =T83 -> 234480 | V83: 234480 | W83: 234480 | X83: 234075 | Y83: 234075 | Z83: 234075 | AA83: 234075 | AB83: 234060 | AC83: 234060 | AD83: 234060 | AE83: 234060 | AF83: 325902 | AG83: 326714 | AH83: 327208 | AI83: 327208 | AJ83: 327208 | AK83: 327208 | AL83: 327208 | AM83: 327208 | AN83: 327208 | AO83: 327208 | AP83: 327208 | AQ83: 327208
A84: 1990.2 | J84: 121018 | K84: 120924 | L84: 120964 | M84: 234387 | N84: =N83*(1-0.003) -> 234063.94 | O84: 234801 | P84: 234642 | Q84: 234578 | R84: 234550 | S84: 234485 | T84: 234300 | U84: =T84 -> 234300 | V84: 234300 | W84: 234300 | X84: 234402 | Y84: 234402 | Z84: 234402 | AA84: 234402 | AB84: 234172 | AC84: 234172 | AD84: 234172 | AE84: 234172 | AF84: 325927 | AG84: 325749 | AH84: 327324 | AI84: 327324 | AJ84: 327324 | AK84: 327324 | AL84: 327324 | AM84: 327324 | AN84: 327324 | AO84: 327324 | AP84: 327324 | AQ84: 327324
A85: 1990.3 | K85: 121725 | L85: 121705 | M85: 235563 | N85: =N84*(1+0.006) -> 235468.32 | O85: 235732 | P85: 236721 | Q85: 236905 | R85: 236737 | S85: 236777 | T85: 236810 | U85: =T85 -> 236810 | V85: 236810 | W85: 236810 | X85: 236973 | Y85: 236973 | Z85: 236973 | AA85: 236973 | AB85: 237649 | AC85: 237649 | AD85: 237649 | AE85: 237649 | AF85: 330909 | AG85: 330671 | AH85: 328675 | AI85: 328675 | AJ85: 328675 | AK85: 328675 | AL85: 328675 | AM85: 328675 | AN85: 328675 | AO85: 328675 | AP85: 328675 | AQ85: 328675
A86: 1990.4 | L86: 121508 | M86: 235766 | N86: =N85*(1+0.002) -> 235939.26 | O86: 235520 | P86: 236472 | Q86: 236378 | R86: 236469 | S86: 236471 | T86: 235797 | U86: =T86 -> 235797 | V86: 235797 | W86: 235797 | X86: 235937 | Y86: 235937 | Z86: 235937 | AA86: 235937 | AB86: 235507 | AC86: 235507 | AD86: 235507 | AE86: 235507 | AF86: 327921 | AG86: 327525 | AH86: 327451 | AI86: 327451 | AJ86: 327451 | AK86: 327451 | AL86: 327451 | AM86: 327451 | AN86: 327451 | AO86: 327451 | AP86: 327451 | AQ86: 327451
A87: 1991.1 | M87: 236589 | N87: =N86*(1+0.002) -> 236411.13 | O87: 236941 | P87: 237708 | Q87: 237179 | R87: 237404 | S87: 237451 | T87: 236776 | U87: =T87 -> 236776 | V87: 236969 | W87: 236776 | X87: 236518 | Y87: 236518 | Z87: 236518 | AA87: 236518 | AB87: 237020 | AC87: 237020 | AD87: 237020 | AE87: 237020 | AF87: 329992 | AG87: 329832 | AH87: 329180 | AI87: 329180 | AJ87: 329180 | AK87: 329180 | AL87: 329180 | AM87: 329180 | AN87: 329180 | AO87: 329180 | AP87: 329180 | AQ87: 329180
A88: 1991.2 | N88: =N87*(1+0.003) -> 237120.37 | O88: 237935 | P88: 238815 | Q88: 238657 | R88: 238709 | S88: 238700 | T88: 237905 | U88: =T88 -> 237905 | V88: 238091 | W88: 238042 | X88: 237423 | Y88: 237423 | Z88: 237423 | AA88: 237423 | AB88: 237309 | AC88: 237309 | AD88: 237309 | AE88: 237309 | AF88: 330438 | AG88: 330355 | AH88: 330198 | AI88: 330198 | AJ88: 330198 | AK88: 330198 | AL88: 330198 | AM88: 330198 | AN88: 330198 | AO88: 330198 | AP88: 330198 | AQ88: 330198
A89: 1991.3 | O89: 238060 | P89: 239301 | Q89: 239458 | R89: 239330 | S89: 239131 | T89: 238694 | U89: =T89 -> 238694 | V89: 238387 | W89: 238593 | X89: 238609 | Y89: 238609 | Z89: 238609 | AA89: 238609 | AB89: 238451 | AC89: 238451 | AD89: 238451 | AE89: 238451 | AF89: 331470 | AG89: 331653 | AH89: 332468 | AI89: 332468 | AJ89: 332468 | AK89: 332468 | AL89: 332468 | AM89: 332468 | AN89: 332468 | AO89: 332468 | AP89: 332468 | AQ89: 332468
A90: 1991.4 | P90: 239994 | Q90: 240523 | R90: 240374 | S90: 240534 | T90: 239806 | U90: =T90 -> 239806 | V90: 239734 | W90: 239770 | X90: 240135 | Y90: 240135 | Z90: 240135 | AA90: 240135 | AB90: 239905 | AC90: 239905 | AD90: 239905 | AE90: 239905 | AF90: 333682 | AG90: 333742 | AH90: 333736 | AI90: 333736 | AJ90: 333736 | AK90: 333736 | AL90: 333736 | AM90: 333736 | AN90: 333736 | AO90: 333736 | AP90: 333736 | AQ90: 333736
A91: 1992.1 | Q91: 241925 | R91: 241702 | S91: 241902 | T91: 241094 | U91: 241005.03 | V91: 241248 | W91: 240903 | X91: 240721 | Y91: 241129 | Z91: 240886 | AA91: 241143 | AB91: 241361 | AC91: 241361 | AD91: 241361 | AE91: 241361 | AF91: 334439 | AG91: 334314 | AH91: 334098 | AI91: 334098 | AJ91: 334390 | AK91: 334389 | AL91: 334389 | AM91: 334389 | AN91: 334389 | AO91: 334389 | AP91: 334389 | AQ91: 334389
A92: 1992.2 | R92: 242225 | S92: 242501 | T92: 241499 | U92: 241487.04 | V92: 241812 | W92: 241662 | X92: 241073 | Y92: 241167 | Z92: 241127 | AA92: 240947 | AB92: 241120 | AC92: 241120 | AD92: 241120 | AE92: 241120 | AF92: 334747 | AG92: 334569 | AH92: 334748 | AI92: 334748 | AJ92: 334639 | AK92: 334639 | AL92: 334639 | AM92: 334639 | AN92: 334639 | AO92: 334639 | AP92: 334639 | AQ92: 334639
A93: 1992.3 | S93: 241022 | T93: 240408 | U93: 240279.6 | V93: 240081 | W93: 240348 | X93: 239237 | Y93: 238848 | Z93: 239006 | AA93: 238874 | AB93: 238584 | AC93: 238584 | AD93: 238584 | AE93: 238584 | AF93: 332043 | AG93: 331994 | AH93: 333113 | AI93: 333113 | AJ93: 333022 | AK93: 333022 | AL93: 333022 | AM93: 333022 | AN93: 333022 | AO93: 333022 | AP93: 333022 | AQ93: 333022
A94: 1992.4 | T94: 239036 | U94: 238837.93 | V94: 238896 | W94: 239123 | X94: 238783 | Y94: 238670 | Z94: 238795 | AA94: 238851 | AB94: 238590 | AC94: 238590 | AD94: 238590 | AE94: 238590 | AF94: 331843 | AG94: 332195 | AH94: 331113 | AI94: 331113 | AJ94: 331021 | AK94: 331022 | AL94: 331022 | AM94: 331022 | AN94: 331022 | AO94: 331022 | AP94: 331022 | AQ94: 331022
A95: 1993.1 | U95: 239315.6 | V95: 238555 | W95: 238636 | X95: 237684 | Y95: 238101 | Z95: 238009 | AA95: 238065 | AB95: 237460 | AC95: 237533 | AD95: 237289 | AE95: 237374 | AF95: 329308 | AG95: 329405 | AH95: 328787 | AI95: 328787 | AJ95: 328965 | AK95: 328964 | AL95: 328964 | AM95: 328964 | AN95: 328964 | AO95: 328964 | AP95: 328964 | AQ95: 328964
A96: 1993.2 | V96: 240372 | W96: 240322 | X96: 238633 | Y96: 238712 | Z96: 238586 | AA96: 238613 | AB96: 237467 | AC96: 237474 | AD96: 237691 | AE96: 237688 | AF96: 330186 | AG96: 329896 | AH96: 329384 | AI96: 329384 | AJ96: 329223 | AK96: 329224 | AL96: 329224 | AM96: 329224 | AN96: 329175 | AO96: 329175 | AP96: 329175 | AQ96: 329175
A97: 1993.3 | W97: 239180 | X97: 237614 | Y97: 237193 | Z97: 237199 | AA97: 236972 | AB97: 235394 | AC97: 235378 | AD97: 235410 | AE97: 235329 | AF97: 327354 | AG97: 327479 | AH97: 328405 | AI97: 328405 | AJ97: 328291 | AK97: 328291 | AL97: 328291 | AM97: 328291 | AN97: 328316 | AO97: 328316 | AP97: 328316 | AQ97: 328316
A98: 1993.4 | X98: 239514 | Y98: 239440 | Z98: 239652 | AA98: 239796 | AB98: 238023 | AC98: 237959 | AD98: 237954 | AE98: 237954 | AF98: 330820 | AG98: 330889 | AH98: 331093 | AI98: 331093 | AJ98: 331189 | AK98: 331190 | AL98: 331190 | AM98: 331190 | AN98: 331214 | AO98: 331214 | AP98: 331214 | AQ98: 331214
A99: 1994.1 | Y99: 239607 | Z99: 240636 | AA99: 240490 | AB99: 238876 | AC99: 238896 | AD99: 238692 | AE99: 238458 | AF99: 331705 | AG99: 331845 | AH99: 331554 | AI99: 331638 | AJ99: 331987 | AK99: 331985 | AL99: 331985 | AM99: 331985 | AN99: 332560 | AO99: 332560 | AP99: 332560 | AQ99: 332560
...

Sheet sec95
A1: YEAR | B1: QTR | C1: PIL971 | D1: PIL972 | E1: PIL973 | F1: PIL974 | G1: PIL981 | H1: PIL982 | I1: PIL983 | J1: PIL984 | K1: PIL991 | L1: PIL992 | M1: PIL993 | N1: PIL994 | O1: PIL001 | P1: PIL002 | Q1: PIL003 | R1: PIL004 | S1: PIL011 | T1: PIL012 | U1: PIL013 | V1: PIL014 | W1: PIL021 | X1: PIL022 | Y1: PIL023 | Z1: PIL024 | AA1: PIL031 | AB1: PIL032 | AC1: PIL033 | AD1: PIL034 | AE1: PIL041 | AF1: PIL042 | AG1: PIL043 | AH1: PIL044 | AI1: PIL051 | AJ1: PIL052 | AK1: PIL053
C2: y36 | D2: y37 | E2: y38 | F2: y39 | G2: y40 | H2: y41 | I2: y42 | J2: y43 | K2: y44 | L2: y45 | M2: y46 | N2: y47 | O2: y48 | P2: y49 | Q2: y50 | R2: y51 | S2: y52 | T2: y53 | U2: y54 | V2: y55 | W2: y56 | X2: y57 | Y2: y58 | Z2: y59 | AA2: y60 | AB2: y61 | AC2: y62 | AD2: y63 | AE2: y64 | AF2: y65 | AG2: y66 | AH2: y67 | AI2: y68 | AJ2: y69 | AK2: y70
A3: 1970 | B3: 1 | C3: 181584 | D3: 181584 | E3: 181584 | F3: 181584 | G3: 181584 | H3: 181584 | I3: 181584 | J3: =J4/I4*I3 -> 228444.11 | K3: =K4/J4*J3 -> 232310.8 | L3: =K3 -> 232310.8 | M3: =M4/L4*L3 -> 233921.13 | N3: =$M3 -> 233921.13 | O3: =$M3 -> 233921.13 | P3: =$M3 -> 233921.13 | Q3: =$M3 -> 233921.13 | R3: 231511 | S3: 231511 | T3: 231511 | U3: 231511 | V3: 119565 | W3: 119565 | X3: 119565 | Y3: 119565 | Z3: 119565 | AA3: =AA4/Z4*Z3 -> 118862.59 | AB3: =$AA3 -> 118862.59 | AC3: =$AA3 -> 118862.59 | AD3: =$AA3 -> 118862.59 | AE3: =$AA3 -> 118862.59 | AF3: =$AA3 -> 118862.59 | AG3: =$AA3 -> 118862.59 | AH3: =AG3 -> 118862.59 | AI3: =AH3 -> 118862.59 | AJ3: =AH3 -> 118862.59 | AK3: =AH3 -> 118862.59
A4: 1970 | B4: 2 | C4: 184060 | D4: 184060 | E4: 184060 | F4: 184060 | G4: 184060 | H4: 184060 | I4: 184060 | J4: =J5/I5*I4 -> 231559.08 | K4: =K5/J5*J4 -> 235478.49 | L4: =K4 -> 235478.49 | M4: =M5/L5*L4 -> 237110.78 | N4: =$M4 -> 237110.78 | O4: =$M4 -> 237110.78 | P4: =$M4 -> 237110.78 | Q4: =$M4 -> 237110.78 | R4: 233201 | S4: 233201 | T4: 233201 | U4: 233201 | V4: 120438 | W4: 120438 | X4: 120438 | Y4: 120438 | Z4: 120438 | AA4: =AA5/Z5*Z4 -> 119730.46 | AB4: =$AA4 -> 119730.46 | AC4: =$AA4 -> 119730.46 | AD4: =$AA4 -> 119730.46 | AE4: =$AA4 -> 119730.46 | AF4: =$AA4 -> 119730.46 | AG4: =$AA4 -> 119730.46 | AH4: =AG4 -> 119730.46 | AI4: =AH4 -> 119730.46 | AJ4: =AH4 -> 119730.46 | AK4: =AH4 -> 119730.46
A5: 1970 | B5: 3 | C5: 186705 | D5: 186705 | E5: 186705 | F5: 186705 | G5: 186705 | H5: 186705 | I5: 186705 | J5: =J6/I6*I5 -> 234886.65 | K5: =K6/J6*J5 -> 238862.39 | L5: =K5 -> 238862.39 | M5: =M6/L6*L5 -> 240518.13 | N5: =$M5 -> 240518.13 | O5: =$M5 -> 240518.13 | P5: =$M5 -> 240518.13 | Q5: =$M5 -> 240518.13 | R5: 237880 | S5: 237880 | T5: 237880 | U5: 237880 | V5: 122855 | W5: 122855 | X5: 122855 | Y5: 122855 | Z5: 122855 | AA5: =AA6/Z6*Z5 -> 122133.26 | AB5: =$AA5 -> 122133.26 | AC5: =$AA5 -> 122133.26 | AD5: =$AA5 -> 122133.26 | AE5: =$AA5 -> 122133.26 | AF5: =$AA5 -> 122133.26 | AG5: =$AA5 -> 122133.26 | AH5: =AG5 -> 122133.26 | AI5: =AH5 -> 122133.26 | AJ5: =AH5 -> 122133.26 | AK5: =AH5 -> 122133.26
A6: 1970 | B6: 4 | C6: 186066 | D6: 186066 | E6: 186066 | F6: 186066 | G6: 186066 | H6: 186066 | I6: 186066 | J6: =J7/I7*I6 -> 234082.75 | K6: =K7/J7*J6 -> 238044.88 | L6: =K6 -> 238044.88 | M6: =M7/L7*L6 -> 239694.96 | N6: =$M6 -> 239694.96 | O6: =$M6 -> 239694.96 | P6: =$M6 -> 239694.96 | Q6: =$M6 -> 239694.96 | R6: 238146 | S6: 238146 | T6: 238146 | U6: 238146 | V6: 122992 | W6: 122992 | X6: 122992 | Y6: 122992 | Z6: 122992 | AA6: =AA7/Z7*Z6 -> 122269.46 | AB6: =$AA6 -> 122269.46 | AC6: =$AA6 -> 122269.46 | AD6: =$AA6 -> 122269.46 | AE6: =$AA6 -> 122269.46 | AF6: =$AA6 -> 122269.46 | AG6: =$AA6 -> 122269.46 | AH6: =AG6 -> 122269.46 | AI6: =AH6 -> 122269.46 | AJ6: =AH6 -> 122269.46 | AK6: =AH6 -> 122269.46
A7: 1971 | B7: 1 | C7: 186657 | D7: 186657 | E7: 186657 | F7: 186657 | G7: 186657 | H7: 186657 | I7: 186657 | J7: =J8/I8*I7 -> 234826.27 | K7: =K8/J8*J7 -> 238800.98 | L7: =K7 -> 238800.98 | M7: =M8/L8*L7 -> 240456.3 | N7: =$M7 -> 240456.3 | O7: =$M7 -> 240456.3 | P7: =$M7 -> 240456.3 | Q7: =$M7 -> 240456.3 | R7: 236900 | S7: 236900 | T7: 236900 | U7: 236900 | V7: 122349 | W7: 122349 | X7: 122349 | Y7: 122349 | Z7: 122349 | AA7: =AA8/Z8*Z7 -> 121630.24 | AB7: =$AA7 -> 121630.24 | AC7: =$AA7 -> 121630.24 | AD7: =$AA7 -> 121630.24 | AE7: =$AA7 -> 121630.24 | AF7: =$AA7 -> 121630.24 | AG7: =$AA7 -> 121630.24 | AH7: =AG7 -> 121630.24 | AI7: =AH7 -> 121630.24 | AJ7: =AH7 -> 121630.24 | AK7: =AH7 -> 121630.24
A8: 1971 | B8: 2 | C8: 186728 | D8: 186728 | E8: 186728 | F8: 186728 | G8: 186728 | H8: 186728 | I8: 186728 | J8: =J9/I9*I8 -> 234915.59 | K8: =K9/J9*J8 -> 238891.82 | L8: =K8 -> 238891.82 | M8: =M9/L9*L8 -> 240547.76 | N8: =$M8 -> 240547.76 | O8: =$M8 -> 240547.76 | P8: =$M8 -> 240547.76 | Q8: =$M8 -> 240547.76 | R8: 237900 | S8: 237900 | T8: 237900 | U8: 237900 | V8: 122865 | W8: 122865 | X8: 122865 | Y8: 122865 | Z8: 122865 | AA8: =AA9/Z9*Z8 -> 122143.21 | AB8: =$AA8 -> 122143.21 | AC8: =$AA8 -> 122143.21 | AD8: =$AA8 -> 122143.21 | AE8: =$AA8 -> 122143.21 | AF8: =$AA8 -> 122143.21 | AG8: =$AA8 -> 122143.21 | AH8: =AG8 -> 122143.21 | AI8: =AH8 -> 122143.21 | AJ8: =AH8 -> 122143.21 | AK8: =AH8 -> 122143.21
A9: 1971 | B9: 3 | C9: 188689 | D9: 188689 | E9: 188689 | F9: 188689 | G9: 188689 | H9: 188689 | I9: 188689 | J9: =J10/I10*I9 -> 237382.65 | K9: =K10/J10*J9 -> 241400.64 | L9: =K9 -> 241400.64 | M9: =M10/L10*L9 -> 243073.97 | N9: =$M9 -> 243073.97 | O9: =$M9 -> 243073.97 | P9: =$M9 -> 243073.97 | Q9: =$M9 -> 243073.97 | R9: 241384 | S9: 241384 | T9: 241384 | U9: 241384 | V9: 124665 | W9: 124665 | X9: 124665 | Y9: 124665 | Z9: 124665 | AA9: =AA10/Z10*Z9 -> 123932.63 | AB9: =$AA9 -> 123932.63 | AC9: =$AA9 -> 123932.63 | AD9: =$AA9 -> 123932.63 | AE9: =$AA9 -> 123932.63 | AF9: =$AA9 -> 123932.63 | AG9: =$AA9 -> 123932.63 | AH9: =AG9 -> 123932.63 | AI9: =AH9 -> 123932.63 | AJ9: =AH9 -> 123932.63 | AK9: =AH9 -> 123932.63
A10: 1971 | B10: 4 | C10: 190328 | D10: 190328 | E10: 190328 | F10: 190328 | G10: 190328 | H10: 190328 | I10: 190328 | J10: =J11/I11*I10 -> 239444.62 | K10: =K11/J11*J10 -> 243497.5 | L10: =K10 -> 243497.5 | M10: =M11/L11*L10 -> 245185.38 | N10: =$M10 -> 245185.38 | O10: =$M10 -> 245185.38 | P10: =$M10 -> 245185.38 | Q10: =$M10 -> 245185.38 | R10: 242747 | S10: 242747 | T10: 242747 | U10: 242747 | V10: 125368 | W10: 125368 | X10: 125368 | Y10: 125368 | Z10: 125368 | AA10: =AA11/Z11*Z10 -> 124631.5 | AB10: =$AA10 -> 124631.5 | AC10: =$AA10 -> 124631.5 | AD10: =$AA10 -> 124631.5 | AE10: =$AA10 -> 124631.5 | AF10: =$AA10 -> 124631.5 | AG10: =$AA10 -> 124631.5 | AH10: =AG10 -> 124631.5 | AI10: =AH10 -> 124631.5 | AJ10: =AH10 -> 124631.5 | AK10: =AH10 -> 124631.5
A11: 1972 | B11: 1 | C11: 192961 | D11: 192961 | E11: 192961 | F11: 192961 | G11: 192961 | H11: 192961 | I11: 192961 | J11: =J12/I12*I11 -> 242757.1 | K11: =K12/J12*J11 -> 246866.05 | L11: =K11 -> 246866.05 | M11: =M12/L12*L11 -> 248577.27 | N11: =$M11 -> 248577.27 | O11: =$M11 -> 248577.27 | P11: =$M11 -> 248577.27 | Q11: =$M11 -> 248577.27 | R11: 245429 | S11: 245429 | T11: 245429 | U11: 245429 | V11: 126754 | W11: 126754 | X11: 126754 | Y11: 126754 | Z11: 126754 | AA11: =AA12/Z12*Z11 -> 126009.36 | AB11: =$AA11 -> 126009.36 | AC11: =$AA11 -> 126009.36 | AD11: =$AA11 -> 126009.36 | AE11: =$AA11 -> 126009.36 | AF11: =$AA11 -> 126009.36 | AG11: =$AA11 -> 126009.36 | AH11: =AG11 -> 126009.36 | AI11: =AH11 -> 126009.36 | AJ11: =AH11 -> 126009.36 | AK11: =AH11 -> 126009.36
A12: 1972 | B12: 2 | C12: 192295 | D12: 192295 | E12: 192295 | F12: 192295 | G12: 192295 | H12: 192295 | I12: 192295 | J12: =J13/I13*I12 -> 241919.23 | K12: =K13/J13*J12 -> 246014 | L12: =K12 -> 246014 | M12: =M13/L13*L12 -> 247719.31 | N12: =$M12 -> 247719.31 | O12: =$M12 -> 247719.31 | P12: =$M12 -> 247719.31 | Q12: =$M12 -> 247719.31 | R12: 245318 | S12: 245318 | T12: 245318 | U12: 245318 | V12: 126696 | W12: 126696 | X12: 126696 | Y12: 126696 | Z12: 126696 | AA12: =AA13/Z13*Z12 -> 125951.7 | AB12: =$AA12 -> 125951.7 | AC12: =$AA12 -> 125951.7 | AD12: =$AA12 -> 125951.7 | AE12: =$AA12 -> 125951.7 | AF12: =$AA12 -> 125951.7 | AG12: =$AA12 -> 125951.7 | AH12: =AG12 -> 125951.7 | AI12: =AH12 -> 125951.7 | AJ12: =AH12 -> 125951.7 | AK12: =AH12 -> 125951.7
A13: 1972 | B13: 3 | C13: 193616 | D13: 193616 | E13: 193616 | F13: 193616 | G13: 193616 | H13: 193616 | I13: 193616 | J13: =J14/I14*I13 -> 243581.13 | K13: =K14/J14*J13 -> 247704.03 | L13: =K13 -> 247704.03 | M13: =M14/L14*L13 -> 249421.06 | N13: =$M13 -> 249421.06 | O13: =$M13 -> 249421.06 | P13: =$M13 -> 249421.06 | Q13: =$M13 -> 249421.06 | R13: 248625 | S13: 248625 | T13: 248625 | U13: 248625 | V13: 128404 | W13: 128404 | X13: 128404 | Y13: 128404 | Z13: 128404 | AA13: =AA14/Z14*Z13 -> 127649.67 | AB13: =$AA13 -> 127649.67 | AC13: =$AA13 -> 127649.67 | AD13: =$AA13 -> 127649.67 | AE13: =$AA13 -> 127649.67 | AF13: =$AA13 -> 127649.67 | AG13: =$AA13 -> 127649.67 | AH13: =AG13 -> 127649.67 | AI13: =AH13 -> 127649.67 | AJ13: =AH13 -> 127649.67 | AK13: =AH13 -> 127649.67
A14: 1972 | B14: 4 | C14: 195546 | D14: 195546 | E14: 195546 | F14: 195546 | G14: 195546 | H14: 195546 | I14: 195546 | J14: =J15/I15*I14 -> 246009.19 | K14: =K15/J15*J14 -> 250173.19 | L14: =K14 -> 250173.19 | M14: =M15/L15*L14 -> 251907.34 | N14: =$M14 -> 251907.34 | O14: =$M14 -> 251907.34 | P14: =$M14 -> 251907.34 | Q14: =$M14 -> 251907.34 | R14: 249807 | S14: 249807 | T14: 249807 | U14: 249807 | V14: 129014 | W14: 129014 | X14: 129014 | Y14: 129014 | Z14: 129014 | AA14: =AA15/Z15*Z14 -> 128256.08 | AB14: =$AA14 -> 128256.08 | AC14: =$AA14 -> 128256.08 | AD14: =$AA14 -> 128256.08 | AE14: =$AA14 -> 128256.08 | AF14: =$AA14 -> 128256.08 | AG14: =$AA14 -> 128256.08 | AH14: =AG14 -> 128256.08 | AI14: =AH14 -> 128256.08 | AJ14: =AH14 -> 128256.08 | AK14: =AH14 -> 128256.08
... A42: 1979 | B42: 4 | C42: 261768 | D42: 261768 | E42: 261768 | F42: 261768 | G42: 261768 | H42: 261768 | I42: 261768 | J42: =J43/I43*I42 -> 329320.64 | K42: =K43/J43*J42 -> 334894.78 | L42: =K42 -> 334894.78 | M42: =M43/L43*L42 -> 337216.2 | N42: =$M42 -> 337216.2 | O42: =$M42 -> 337216.2 | P42: =$M42 -> 337216.2 | Q42: =$M42 -> 337216.2 | R42: 333170 | S42: 333170 | T42: 333170 | U42: 333170 | V42: 172068 | W42: 172068 | X42: 172068 | Y42: 172068 | Z42: 172068 | AA42: =AA43/Z43*Z42 -> 171057.15 | AB42: =$AA42 -> 171057.15 | AC42: =$AA42 -> 171057.15 | AD42: =$AA42 -> 171057.15 | AE42: =$AA42 -> 171057.15 | AF42: =$AA42 -> 171057.15 | AG42: =$AA42 -> 171057.15 | AH42: =AG42 -> 171057.15 | AI42: =AH42 -> 171057.15 | AJ42: =AH42 -> 171057.15 | AK42: =AH42 -> 171057.15
A43: 1980 | B43: 1 | C43: 264158 | D43: 264158 | E43: 264158 | F43: 264158 | G43: 264158 | H43: 264158 | I43: 264158 | J43: =J44/I44*I43 -> 332327.41 | K43: =K44/J44*J43 -> 337952.45 | L43: =K43 -> 337952.45 | M43: =M44/L44*L43 -> 340295.06 | N43: =$M43 -> 340295.06 | O43: =$M43 -> 340295.06 | P43: =$M43 -> 340295.06 | Q43: =$M43 -> 340295.06 | R43: 334539 | S43: 334539 | T43: 334539 | U43: 334539 | V43: 172775 | W43: 172775 | X43: 172775 | Y43: 172775 | Z43: 172775 | AA43: 171760 | AB43: 171760 | AC43: 171760 | AD43: 171760 | AE43: 171760 | AF43: 171760 | AG43: 171760 | AH43: =AG43 -> 171760 | AI43: 171760 | AJ43: 171760 | AK43: 171760
A44: 1980 | B44: 2 | C44: 263883 | D44: 263883 | E44: 263883 | F44: 263883 | G44: 263883 | H44: 263883 | I44: 263883 | J44: =J45/I45*I44 -> 331981.44 | K44: =K45/J45*J44 -> 337600.62 | L44: =K44 -> 337600.62 | M44: =M45/L45*L44 -> 339940.8 | N44: =$M44 -> 339940.8 | O44: =$M44 -> 339940.8 | P44: =$M44 -> 339940.8 | Q44: =$M44 -> 339940.8 | R44: 335243 | S44: 335243 | T44: 335243 | U44: 335243 | V44: 173139 | W44: 173139 | X44: 173139 | Y44: 173139 | Z44: 173139 | AA44: 173093 | AB44: 173093 | AC44: 173093 | AD44: 173093 | AE44: 173093 | AF44: 173093 | AG44: 173093 | AH44: =AG44 -> 173093 | AI44: 173093 | AJ44: 173093 | AK44: 173093
A45: 1980 | B45: 3 | C45: 261165 | D45: 261165 | E45: 261165 | F45: 261165 | G45: 261165 | H45: 261165 | I45: 261165 | J45: =J46/I46*I45 -> 328562.02 | K45: =K46/J46*J45 -> 334123.33 | L45: =K45 -> 334123.33 | M45: =M46/L46*L45 -> 336439.4 | N45: =$M45 -> 336439.4 | O45: =$M45 -> 336439.4 | P45: =$M45 -> 336439.4 | Q45: =$M45 -> 336439.4 | R45: 334707 | S45: 334707 | T45: 334707 | U45: 334707 | V45: 172862 | W45: 172862 | X45: 172862 | Y45: 172862 | Z45: 172862 | AA45: 173238 | AB45: 173238 | AC45: 173238 | AD45: 173238 | AE45: 173238 | AF45: 173238 | AG45: 173238 | AH45: =AG45 -> 173238 | AI45: 173238 | AJ45: 173238 | AK45: 173238
A46: 1980 | B46: 4 | C46: 261835 | D46: 261835 | E46: 261835 | F46: 261835 | G46: 261835 | H46: 261835 | I46: 261835 | J46: =J47/I47*I46 -> 329404.93 | K46: =K47/J47*J46 -> 334980.5 | L46: =K46 -> 334980.5 | M46: =M47/L47*L46 -> 337302.51 | N46: =$M46 -> 337302.51 | O46: =$M46 -> 337302.51 | P46: =$M46 -> 337302.51 | Q46: =$M46 -> 337302.51 | R46: 336905 | S46: 336905 | T46: 336905 | U46: 336905 | V46: 173997 | W46: 173997 | X46: 173997 | Y46: 173997 | Z46: 173997 | AA46: 174714 | AB46: 174714 | AC46: 174714 | AD46: 174714 | AE46: 174714 | AF46: 174714 | AG46: 174714 | AH46: =AG46 -> 174714 | AI46: 174714 | AJ46: 174714 | AK46: 174714
A47: 1981 | B47: 1 | C47: 261412 | D47: 261412 | E47: 261412 | F47: 261412 | G47: 261412 | H47: 261412 | I47: 261412 | J47: =J48/I48*I47 -> 328872.77 | K47: =K48/J48*J47 -> 334439.33 | L47: =K47 -> 334439.33 | M47: =M48/L48*L47 -> 336757.59 | N47: =$M47 -> 336757.59 | O47: =$M47 -> 336757.59 | P47: =$M47 -> 336757.59 | Q47: =$M47 -> 336757.59 | R47: 336436 | S47: 336436 | T47: 336436 | U47: 336436 | V47: 173755 | W47: 173755 | X47: 173755 | Y47: 173755 | Z47: 173755 | AA47: 174147 | AB47: 174147 | AC47: 174147 | AD47: 174147 | AE47: 174147 | AF47: 174147 | AG47: 174147 | AH47: =AG47 -> 174147 | AI47: 174147 | AJ47: 174147 | AK47: 174147
A48: 1981 | B48: 2 | C48: 264612 | D48: 264612 | E48: 264612 | F48: 264612 | G48: 264612 | H48: 264612 | I48: 264612 | J48: =J49/I49*I48 -> 332898.57 | K48: =K49/J49*J48 -> 338533.27 | L48: =K48 -> 338533.27 | M48: =M49/L49*L48 -> 340879.92 | N48: =$M48 -> 340879.92 | O48: =$M48 -> 340879.92 | P48: =$M48 -> 340879.92 | Q48: =$M48 -> 340879.92 | R48: 338745 | S48: 338745 | T48: 338745 | U48: 338745 | V48: 174947 | W48: 174947 | X48: 174947 | Y48: 174947 | Z48: 174947 | AA48: 174209 | AB48: 174209 | AC48: 174209 | AD48: 174209 | AE48: 174209 | AF48: 174209 | AG48: 174209 | AH48: =AG48 -> 174209 | AI48: 174209 | AJ48: 174209 | AK48: 174209
A49: 1981 | B49: 3 | C49: 264836 | D49: 264836 | E49: 264836 | F49: 264836 | G49: 264836 | H49: 264836 | I49: 264836 | J49: =J50/I50*I49 -> 333180.37 | K49: =K50/J50*J49 -> 338819.85 | L49: =K49 -> 338819.85 | M49: =M50/L50*L49 -> 341168.48 | N49: =$M49 -> 341168.48 | O49: =$M49 -> 341168.48 | P49: =$M49 -> 341168.48 | Q49: =$M49 -> 341168.48 | R49: 337087 | S49: 337087 | T49: 337087 | U49: 337087 | V49: 174091 | W49: 174091 | X49: 174091 | Y49: 174091 | Z49: 174091 | AA49: 173586 | AB49: 173586 | AC49: 173586 | AD49: 173586 | AE49: 173586 | AF49: 173586 | AG49: 173586 | AH49: =AG49 -> 173586 | AI49: 173586 | AJ49: 173586 | AK49: 173586
A50: 1981 | B50: 4 | C50: 265163 | D50: 265163 | E50: 265163 | F50: 265163 | G50: 265163 | H50: 265163 | I50: 265163 | J50: =J51/I51*I50 -> 333591.76 | K50: =K51/J51*J50 -> 339238.2 | L50: =K50 -> 339238.2 | M50: =M51/L51*L50 -> 341589.73 | N50: =$M50 -> 341589.73 | O50: =$M50 -> 341589.73 | P50: =$M50 -> 341589.73 | Q50: =$M50 -> 341589.73 | R50: 339600 | S50: 339600 | T50: 339600 | U50: 339600 | V50: 175389 | W50: 175389 | X50: 175389 | Y50: 175389 | Z50: 175389 | AA50: 175520 | AB50: 175520 | AC50: 175520 | AD50: 175520 | AE50: 175520 | AF50: 175520 | AG50: 175520 | AH50: =AG50 -> 175520 | AI50: 175520 | AJ50: 175520 | AK50: 175520
A51: 1982 | B51: 1 | C51: 265556 | D51: 265556 | E51: 265556 | F51: 265556 | G51: 265556 | H51: 265556 | I51: 265556 | J51: =J52/I52*I51 -> 334086.18 | K51: =K52/J52*J51 -> 339740.99 | L51: =K51 -> 339740.99 | M51: 342096 | N51: 342096 | O51: 342096 | P51: 342096 | Q51: 342096 | R51: 340407 | S51: 340407 | T51: 340407 | U51: 340407 | V51: 175806 | W51: 175806 | X51: 175806 | Y51: 175806 | Z51: 175806 | AA51: 176774 | AB51: 176774 | AC51: 176774 | AD51: 176774 | AE51: 176774 | AF51: 176774 | AG51: 176774 | AH51: =AG51 -> 176774 | AI51: 176774 | AJ51: 176774 | AK51: 176774
A52: 1982 | B52: 2 | C52: 266214 | D52: 266214 | E52: 266214 | F52: 266214 | G52: 266214 | H52: 266214 | I52: 266214 | J52: =J53/I53*I52 -> 334913.98 | K52: =K53/J53*J52 -> 340582.8 | L52: =K52 -> 340582.8 | M52: 340584 | N52: 340584 | O52: 340584 | P52: 340584 | Q52: 340584 | R52: 340275 | S52: 340275 | T52: 340275 | U52: 340275 | V52: 175737 | W52: 175737 | X52: 175737 | Y52: 175737 | Z52: 175737 | AA52: 176023 | AB52: 176023 | AC52: 176023 | AD52: 176023 | AE52: 176023 | AF52: 176023 | AG52: 176023 | AH52: =AG52 -> 176023 | AI52: 176023 | AJ52: 176023 | AK52: 176023
A53: 1982 | B53: 3 | C53: 264634 | D53: 264634 | E53: 264634 | F53: 264634 | G53: 264634 | H53: 264634 | I53: 264634 | J53: =J54/I54*I53 -> 332926.24 | K53: =K54/J54*J53 -> 338561.42 | L53: =K53 -> 338561.42 | M53: 338808 | N53: 338808 | O53: 338808 | P53: 338808 | Q53: 338808 | R53: 339761 | S53: 339761 | T53: 339761 | U53: 339761 | V53: 175472 | W53: 175472 | X53: 175472 | Y53: 175472 | Z53: 175472 | AA53: 174714 | AB53: 174714 | AC53: 174714 | AD53: 174714 | AE53: 174714 | AF53: 174714 | AG53: 174714 | AH53: =AG53 -> 174714 | AI53: 174714 | AJ53: 174714 | AK53: 174714
A54: 1982 | B54: 4 | C54: 264456 | D54: 264456 | E54: 264456 | F54: 264456 | G54: 264456 | H54: 264456 | I54: 264456 | J54: =J55/I55*I54 -> 332702.31 | K54: =K55/J55*J54 -> 338333.69 | L54: =K54 -> 338333.69 | M54: 338911 | N54: 338911 | O54: 338911 | P54: 338911 | Q54: 338911 | R54: 339956 | S54: 339956 | T54: 339956 | U54: 339956 | V54: 175573 | W54: 175573 | X54: 175573 | Y54: 175573 | Z54: 175573 | AA54: 174288 | AB54: 174288 | AC54: 174288 | AD54: 174288 | AE54: 174288 | AF54: 174288 | AG54: 174288 | AH54: =AG54 -> 174288 | AI54: 174288 | AJ54: 174288 | AK54: 174288
A55: 1983 | B55: 1 | C55: 265661 | D55: 265661 | E55: 265661 | F55: 265661 | G55: 265661 | H55: 265661 | I55: 265661 | J55: =J56/I56*I55 -> 334218.28 | K55: =K56/J56*J55 -> 339875.32 | L55: =K55 -> 339875.32 | M55: 340309 | N55: 340309 | O55: 340309 | P55: 340309 | Q55: 340309 | R55: 342196 | S55: 342196 | T55: 342196 | U55: 342196 | V55: 176730 | W55: 176730 | X55: 176730 | Y55: 176730 | Z55: 176730 | AA55: 175969 | AB55: 175969 | AC55: 175969 | AD55: 175969 | AE55: 175969 | AF55: 175969 | AG55: 175969 | AH55: =AG55 -> 175969 | AI55: 175969 | AJ55: 175969 | AK55: 175969
A56: 1983 | B56: 2 | C56: 266849 | D56: 266849 | E56: 266849 | F56: 266849 | G56: 266849 | H56: 266849 | I56: 266849 | J56: =J57/I57*I56 -> 335712.85 | K56: =K57/J57*J56 -> 341395.2 | L56: =K56 -> 341395.2 | M56: 340915 | N56: 340915 | O56: 340915 | P56: 340915 | Q56: 340915 | R56: 341036 | S56: 341036 | T56: 341036 | U56: 341036 | V56: 176130 | W56: 176130 | X56: 176130 | Y56: 176130 | Z56: 176130 | AA56: 176049 | AB56: 176049 | AC56: 176049 | AD56: 176049 | AE56: 176049 | AF56: 176049 | AG56: 176049 | AH56: =AG56 -> 176049 | AI56: 176049 | AJ56: 176049 | AK56: 176049
A57: 1983 | B57: 3 | C57: 269003 | D57: 269003 | E57: 269003 | F57: 269003 | G57: 269003 | H57: 269003 | I57: 269003 | J57: =J58/I58*I57 -> 338422.72 | K57: =K58/J58*J57 -> 344150.93 | L57: =K57 -> 344150.93 | M57: 345446 | N57: 345446 | O57: 345446 | P57: 345446 | Q57: 345446 | R57: 344088 | S57: 344088 | T57: 344088 | U57: 344088 | V57: 177706 | W57: 177706 | X57: 177706 | Y57: 177706 | Z57: 177706 | AA57: 178110 | AB57: 178110 | AC57: 178110 | AD57: 178110 | AE57: 178110 | AF57: 178110 | AG57: 178110 | AH57: =AG57 -> 178110 | AI57: 178110 | AJ57: 178110 | AK57: 178110
A58: 1983 | B58: 4 | C58: 272270 | D58: 272270 | E58: 272270 | F58: 272270 | G58: 272270 | H58: 272270 | I58: 272270 | J58: =J59/I59*I58 -> 342532.81 | K58: =K59/J59*J58 -> 348330.59 | L58: =K58 -> 348330.59 | M58: 350550 | N58: 350550 | O58: 350550 | P58: 350550 | Q58: 350550 | R58: 349900 | S58: 349900 | T58: 349900 | U58: 349900 | V58: 180708 | W58: 180708 | X58: 180708 | Y58: 180708 | Z58: 180708 | AA58: 181297 | AB58: 181297 | AC58: 181297 | AD58: 181297 | AE58: 181297 | AF58: 181297 | AG58: 181297 | AH58: =AG58 -> 181297 | AI58: 181297 | AJ58: 181297 | AK58: 181297
A59: 1984 | B59: 1 | C59: 274999 | D59: 274999 | E59: 274999 | F59: 274999 | G59: 274999 | H59: 274999 | I59: 274999 | J59: =J60/I60*I59 -> 345966.07 | K59: =K60/J60*J59 -> 351821.96 | L59: =K59 -> 351821.96 | M59: 352498 | N59: 352498 | O59: 352498 | P59: 352498 | Q59: 352498 | R59: 353094 | S59: 353094 | T59: 353094 | U59: 353094 | V59: 182358 | W59: 182358 | X59: 182358 | Y59: 182358 | Z59: 182358 | AA59: 181858 | AB59: 181858 | AC59: 181858 | AD59: 181858 | AE59: 181858 | AF59: 181858 | AG59: 181858 | AH59: =AG59 -> 181858 | AI59: 181858 | AJ59: 181858 | AK59: 181858
A60: 1984 | B60: 2 | C60: 275127 | D60: 275127 | E60: 275127 | F60: 275127 | G60: 275127 | H60: 275127 | I60: 275127 | J60: =J61/I61*I60 -> 346127.1 | K60: =K61/J61*J60 -> 351985.71 | L60: =K60 -> 351985.71 | M60: 351158 | N60: 351158 | O60: 351158 | P60: 351158 | Q60: 351158 | R60: 352450 | S60: 352450 | T60: 352450 | U60: 352450 | V60: 182025 | W60: 182025 | X60: 182025 | Y60: 182025 | Z60: 182025 | AA60: 181782 | AB60: 181782 | AC60: 181782 | AD60: 181782 | AE60: 181782 | AF60: 181782 | AG60: 181782 | AH60: =AG60 -> 181782 | AI60: 181782 | AJ60: 181782 | AK60: 181782
A61: 1984 | B61: 3 | C61: 275272 | D61: 275272 | E61: 275272 | F61: 275272 | G61: 275272 | H61: 275272 | I61: 275272 | J61: =J62/I62*I61 -> 346309.52 | K61: =K62/J62*J61 -> 352171.22 | L61: =K61 -> 352171.22 | M61: 354297 | N61: 354297 | O61: 354297 | P61: 354297 | Q61: 354297 | R61: 353661 | S61: 353661 | T61: 353661 | U61: 353661 | V61: 182651 | W61: 182651 | X61: 182651 | Y61: 182651 | Z61: 182651 | AA61: 183042 | AB61: 183042 | AC61: 183042 | AD61: 183042 | AE61: 183042 | AF61: 183042 | AG61: 183042 | AH61: =AG61 -> 183042 | AI61: 183042 | AJ61: 183042 | AK61: 183042
A62: 1984 | B62: 4 | C62: 275968 | D62: 275968 | E62: 275968 | F62: 275968 | G62: 275968 | H62: 275968 | I62: 275968 | J62: =J63/I63*I62 -> 347185.13 | K62: =K63/J63*J62 -> 353061.65 | L62: =K62 -> 353061.65 | M62: 357256 | N62: 357256 | O62: 357256 | P62: 357256 | Q62: 357256 | R62: 356004 | S62: 356004 | T62: 356004 | U62: 356004 | V62: 183861 | W62: 183861 | X62: 183861 | Y62: 183861 | Z62: 183861 | AA62: 184381 | AB62: 184381 | AC62: 184381 | AD62: 184381 | AE62: 184381 | AF62: 184381 | AG62: 184381 | AH62: =AG62 -> 184381 | AI62: 184381 | AJ62: 184381 | AK62: 184381
... A74: 1987 | B74: 4 | C74: 305082 | D74: 305082 | E74: 305082 | F74: 305082 | G74: 305082 | H74: 305082 | I74: 305082 | J74: =J75/I75*I74 -> 383812.38 | K74: =K75/J75*J74 -> 390308.86 | L74: =K74 -> 390308.86 | M74: 391290 | N74: 391290 | O74: 391290 | P74: 391290 | Q74: 391290 | R74: 389648 | S74: 389648 | T74: 389648 | U74: 389648 | V74: 201237 | W74: 201237 | X74: 201237 | Y74: 201237 | Z74: 201237 | AA74: 201608 | AB74: 201608 | AC74: 201608 | AD74: 201608 | AE74: 201608 | AF74: 201608 | AG74: 201608 | AH74: =AG74 -> 201608 | AI74: 201608 | AJ74: 201608 | AK74: 201608
A75: 1988 | B75: 1 | C75: 308723 | D75: 308723 | E75: 308723 | F75: 308723 | G75: 308723 | H75: 308723 | I75: 308723 | J75: =J76/K76*K75 -> 388392.98 | K75: 394967 | L75: 394967 | M75: 394746 | N75: 394746 | O75: 394746 | P75: 394746 | Q75: 394746 | R75: 395342 | S75: 395342 | T75: 395342 | U75: 395342 | V75: 204177 | W75: 204177 | X75: 204177 | Y75: 204177 | Z75: 204177 | AA75: 204426 | AB75: 204426 | AC75: 204426 | AD75: 204426 | AE75: 204426 | AF75: 204426 | AG75: 204426 | AH75: =AG75 -> 204426 | AI75: 204426 | AJ75: 204426 | AK75: 204426
A76: 1988 | B76: 2 | C76: 310305 | D76: 310305 | E76: 310305 | F76: 310305 | G76: 310305 | H76: 310305 | I76: 310305 | J76: =J77/K77*K76 -> 391219.15 | K76: 397841 | L76: 397841 | M76: 397781 | N76: 397781 | O76: 397781 | P76: 397781 | Q76: 397781 | R76: 398994 | S76: 398994 | T76: 398994 | U76: 398994 | V76: 206063 | W76: 206063 | X76: 206063 | Y76: 206063 | Z76: 206063 | AA76: 205275 | AB76: 205275 | AC76: 205275 | AD76: 205275 | AE76: 205275 | AF76: 205275 | AG76: 205275 | AH76: =AG76 -> 205275 | AI76: 205275 | AJ76: 205275 | AK76: 205275
A77: 1988 | B77: 3 | C77: 312467 | D77: 312467 | E77: 312467 | F77: 312467 | G77: 312467 | H77: 312467 | I77: 312467 | J77: =J78/K78*K77 -> 394703.18 | K77: 401384 | L77: 401384 | M77: 401096 | N77: 401096 | O77: 401096 | P77: 401096 | Q77: 401096 | R77: 401295 | S77: 401295 | T77: 401295 | U77: 401295 | V77: 207252 | W77: 207252 | X77: 207252 | Y77: 207252 | Z77: 207252 | AA77: 206999 | AB77: 206999 | AC77: 206999 | AD77: 206999 | AE77: 206999 | AF77: 206999 | AG77: 206999 | AH77: =AG77 -> 206999 | AI77: 206999 | AJ77: 206999 | AK77: 206999
A78: 1988 | B78: 4 | C78: 315470 | D78: 315470 | E78: 315470 | F78: 315470 | G78: 315470 | H78: 315470 | I78: 315470 | J78: =J79/K79*K78 -> 398536.3 | K78: 405282 | L78: 405282 | M78: 405850 | N78: 405850 | O78: 405850 | P78: 405850 | Q78: 405850 | R78: 403842 | S78: 403842 | T78: 403842 | U78: 403842 | V78: 208567 | W78: 208567 | X78: 208567 | Y78: 208567 | Z78: 208567 | AA78: 209734 | AB78: 209734 | AC78: 209734 | AD78: 209734 | AE78: 209734 | AF78: 209734 | AG78: 209734 | AH78: =AG78 -> 209734 | AI78: 209734 | AJ78: 209734 | AK78: 209734
...

Sheet chainindex
A1: YEAR | B1: QTR | C1: GDP054 | D1: GDP061 | E1: GDP062 | F1: GDP063 | G1: GDP064 | H1: GDP071 | I1: GDP072 | J1: GDP073 | K1: GDP074 | L1: GDP081 | M1: GDP082 | N1: GDP083 | O1: GDP084 | P1: GDP091 | Q1: GDP092 | R1: GDP093 | S1: GDP094 | T1: GDP101 | U1: GDP102 | V1: GDP103 | W1: GDP104 | X1: GDP111 | Y1: GDP112 | Z1: GDP113 | AA1: GDP114 | AB1: GDP121 | AC1: GDP122 | AD1: GDP123 | AE1: GDP124 | AF1: GDP131 | AG1: GDP102 | AH1: GDP103 | AI1: GDP104 | AJ1: GDP141 | AK1: GDP142
C2: y71 | D2: y72 | E2: y73 | F2: y74 | G2: y75 | H2: y76 | I2: y77 | J2: y78 | K2: y79 | L2: y80 | M2: y81 | N2: y82 | O2: y83 | P2: y84 | Q2: y85 | R2: y86 | S2: y87 | T2: y88 | U2: y89 | V2: y90 | W2: y91 | X2: y92 | Y2: y93 | Z2: y94 | AA2: y95 | AB2: y96 | AC2: y97 | AD2: y98 | AE2: y99 | AF2: y100 | AG2: y101 | AH2: y102 | AI2: y103 | AJ2: y104 | AK2: y105
A3: 1970 | B3: 1 | C3: ='sec95'!AK3/'sec95'!AK4*C4 -> 137233.89 | D3: =C3/C4*D4 -> 137414.76 | E3: =D3/D4*E4 -> 137414.76 | F3: =E3/E4*F4 -> 137414.76 | G3: =F3/F4*G4 -> 137414.76 | H3: =G3/G4*H4 -> 137414.76 | I3: =H3/H4*I4 -> 137414.76 | J3: =I3/I4*J4 -> 137414.76 | K3: =J3/J4*K4 -> 137420.9 | ... S3: =R3/R4*S4 -> 137420.9 | T3: =T4*S3/S4 -> 137420.9 | U3: =U4*T3/T4 -> 137420.9 | V3: =V4*U3/U4 -> 137420.9 | W3: =W4*V3/V4 -> 137420.9 | X3: =X4*W3/W4 -> 137420.9 | Y3: =Y4*X3/X4 -> 137420.9 | Z3: =Z4*Y3/Y4 -> 157996.96 | AA3: =AA4*Z3/Z4 -> 157996.96 | ... AK3: =AK4*AJ3/AJ4 -> 157996.96
A4: 1970 | B4: 2 | C4: ='sec95'!AK4/'sec95'!AK5*C5 -> 138235.89 | D4: =C4/C5*D5 -> 138418.09 | E4: =D4/D5*E5 -> 138418.09 | F4: =E4/E5*F5 -> 138418.09 | G4: =F4/F5*G5 -> 138418.09 | H4: =G4/G5*H5 -> 138418.09 | I4: =H4/H5*I5 -> 138418.09 | J4: =I4/I5*J5 -> 138418.09 | K4: =J4/J5*K5 -> 138424.28 | ... S4: =R4/R5*S5 -> 138424.28 | T4: =T5*S4/S5 -> 138424.28 | U4: =U5*T4/T5 -> 138424.28 | V4: =V5*U4/U5 -> 138424.28 | W4: =W5*V4/V5 -> 138424.28 | X4: =X5*W4/W5 -> 138424.28 | Y4: =Y5*X4/X5 -> 138424.28 | Z4: =Z5*Y4/Y5 -> 159150.57 | AA4: =AA5*Z4/Z5 -> 159150.57 | ... AK4: =AK5*AJ4/AJ5 -> 159150.57
A5: 1970 | B5: 3 | C5: ='sec95'!AK5/'sec95'!AK6*C6 -> 141010.07 | D5: =C5/C6*D6 -> 141195.92 | E5: =D5/D6*E6 -> 141195.92 | F5: =E5/E6*F6 -> 141195.92 | G5: =F5/F6*G6 -> 141195.92 | H5: =G5/G6*H6 -> 141195.92 | I5: =H5/H6*I6 -> 141195.92 | J5: =I5/I6*J6 -> 141195.92 | K5: =J5/J6*K6 -> 141202.23 | ... S5: =R5/R6*S6 -> 141202.23 | T5: =T6*S5/S6 -> 141202.23 | U5: =U6*T5/T6 -> 141202.23 | V5: =V6*U5/U6 -> 141202.23 | W5: =W6*V5/V6 -> 141202.23 | X5: =X6*W5/W6 -> 141202.23 | Y5: =Y6*X5/X6 -> 141202.23 | Z5: =Z6*Y5/Y6 -> 162344.47 | AA5: =AA6*Z5/Z6 -> 162344.47 | ... AK5: =AK6*AJ5/AJ6 -> 162344.47
A6: 1970 | B6: 4 | C6: ='sec95'!AK6/'sec95'!AK7*C7 -> 141167.31 | D6: =C6/C7*D7 -> 141353.37 | E6: =D6/D7*E7 -> 141353.37 | F6: =E6/E7*F7 -> 141353.37 | G6: =F6/F7*G7 -> 141353.37 | H6: =G6/G7*H7 -> 141353.37 | I6: =H6/H7*I7 -> 141353.37 | J6: =I6/I7*J7 -> 141353.37 | K6: =J6/J7*K7 -> 141359.69 | ... S6: =R6/R7*S7 -> 141359.69 | T6: =T7*S6/S7 -> 141359.69 | U6: =U7*T6/T7 -> 141359.69 | V6: =V7*U6/U7 -> 141359.69 | W6: =W7*V6/V7 -> 141359.69 | X6: =X7*W6/W7 -> 141359.69 | Y6: =Y7*X6/X7 -> 141359.69 | Z6: =Z7*Y6/Y7 -> 162525.51 | AA6: =AA7*Z6/Z7 -> 162525.51 | ... AK6: =AK7*AJ6/AJ7 -> 162525.51
A7: 1971 | B7: 1 | C7: ='sec95'!AK7/'sec95'!AK8*C8 -> 140429.29 | D7: =C7/C8*D8 -> 140614.38 | E7: =D7/D8*E8 -> 140614.38 | F7: =E7/E8*F8 -> 140614.38 | G7: =F7/F8*G8 -> 140614.38 | H7: =G7/G8*H8 -> 140614.38 | I7: =H7/H8*I8 -> 140614.38 | J7: =I7/I8*J8 -> 140614.38 | K7: =J7/J8*K8 -> 140620.67 | ... S7: =R7/R8*S8 -> 140620.67 | T7: =T8*S7/S8 -> 140620.67 | U7: =U8*T7/T8 -> 140620.67 | V7: =V8*U7/U8 -> 140620.67 | W7: =W8*V7/V8 -> 140620.67 | X7: =X8*W7/W8 -> 140620.67 | Y7: =Y8*X7/X8 -> 140620.67 | Z7: =Z8*Y7/Y8 -> 161675.82 | AA7: =AA8*Z7/Z8 -> 161675.82 | ... AK7: =AK8*AJ7/AJ8 -> 161675.82
A8: 1971 | B8: 2 | C8: ='sec95'!AK8/'sec95'!AK9*C9 -> 141021.55 | D8: =C8/C9*D9 -> 141207.41 | E8: =D8/D9*E9 -> 141207.41 | F8: =E8/E9*F9 -> 141207.41 | G8: =F8/F9*G9 -> 141207.41 | H8: =G8/G9*H9 -> 141207.41 | I8: =H8/H9*I9 -> 141207.41 | J8: =I8/I9*J9 -> 141207.41 | K8: =J8/J9*K9 -> 141213.73 | ... S8: =R8/R9*S9 -> 141213.73 | T8: =T9*S8/S9 -> 141213.73 | U8: =U9*T8/T9 -> 141213.73 | V8: =V9*U8/U9 -> 141213.73 | W8: =W9*V8/V9 -> 141213.73 | X8: =X9*W8/W9 -> 141213.73 | Y8: =Y9*X8/X9 -> 141213.73 | Z8: =Z9*Y8/Y9 -> 162357.68 | AA8: =AA9*Z8/Z9 -> 162357.68 | ... AK8: =AK9*AJ8/AJ9 -> 162357.68
A9: 1971 | B9: 3 | C9: ='sec95'!AK9/'sec95'!AK10*C10 -> 143087.54 | D9: =C9/C10*D10 -> 143276.13 | E9: =D9/D10*E10 -> 143276.13 | F9: =E9/E10*F10 -> 143276.13 | G9: =F9/F10*G10 -> 143276.13 | H9: =G9/G10*H10 -> 143276.13 | I9: =H9/H10*I10 -> 143276.13 | J9: =I9/I10*J10 -> 143276.13 | K9: =J9/J10*K10 -> 143282.54 | ... S9: =R9/R10*S10 -> 143282.54 | T9: =T10*S9/S10 -> 143282.54 | U9: =U10*T9/T10 -> 143282.54 | V9: =V10*U9/U10 -> 143282.54 | W9: =W10*V9/V10 -> 143282.54 | X9: =X10*W9/W10 -> 143282.54 | Y9: =Y10*X9/X10 -> 143282.54 | Z9: =Z10*Y9/Y10 -> 164736.26 | AA9: =AA10*Z9/Z10 -> 164736.26 | ... AK9: =AK10*AJ9/AJ10 -> 164736.26
A10: 1971 | B10: 4 | C10: ='sec95'!AK10/'sec95'!AK11*C11 -> 143894.43 | D10: =C10/C11*D11 -> 144084.08 | E10: =D10/D11*E11 -> 144084.08 | F10: =E10/E11*F11 -> 144084.08 | G10: =F10/F11*G11 -> 144084.08 | H10: =G10/G11*H11 -> 144084.08 | I10: =H10/H11*I11 -> 144084.08 | J10: =I10/I11*J11 -> 144084.08 | K10: =J10/J11*K11 -> 144090.52 | ... S10: =R10/R11*S11 -> 144090.52 | T10: =T11*S10/S11 -> 144090.52 | U10: =U11*T10/T11 -> 144090.52 | V10: =V11*U10/U11 -> 144090.52 | W10: =W11*V10/V11 -> 144090.52 | X10: =X11*W10/W11 -> 144090.52 | Y10: =Y11*X10/X11 -> 144090.52 | Z10: =Z11*Y10/Y11 -> 165665.23 | AA10: =AA11*Z10/Z11 -> 165665.23 | ... AK10: =AK11*AJ10/AJ11 -> 165665.23
A11: 1972 | B11: 1 | C11: ='sec95'!AK11/'sec95'!AK12*C12 -> 145485.25 | D11: =C11/C12*D12 -> 145677 | E11: =D11/D12*E12 -> 145677 | F11: =E11/E12*F12 -> 145677 | G11: =F11/F12*G12 -> 145677 | H11: =G11/G12*H12 -> 145677 | I11: =H11/H12*I12 -> 145677 | J11: =I11/I12*J12 -> 145677 | K11: =J11/J12*K12 -> 145683.51 | ... S11: =R11/R12*S12 -> 145683.51 | T11: =T12*S11/S12 -> 145683.51 | U11: =U12*T11/T12 -> 145683.51 | V11: =V12*U11/U12 -> 145683.51 | W11: =W12*V11/V12 -> 145683.51 | X11: =X12*W11/W12 -> 145683.51 | Y11: =Y12*X11/X12 -> 145683.51 | Z11: =Z12*Y11/Y12 -> 167496.73 | AA11: =AA12*Z11/Z12 -> 167496.73 | ... AK11: =AK12*AJ11/AJ12 -> 167496.73
A12: 1972 | B12: 2 | C12: ='sec95'!AK12/'sec95'!AK13*C13 -> 145418.68 | D12: =C12/C13*D13 -> 145610.34 | E12: =D12/D13*E13 -> 145610.34 | F12: =E12/E13*F13 -> 145610.34 | G12: =F12/F13*G13 -> 145610.34 | H12: =G12/G13*H13 -> 145610.34 | I12: =H12/H13*I13 -> 145610.34 | J12: =I12/I13*J13 -> 145610.34 | K12: =J12/J13*K13 -> 145616.85 | ... S12: =R12/R13*S13 -> 145616.85 | T12: =T13*S12/S13 -> 145616.85 | U12: =U13*T12/T13 -> 145616.85 | V12: =V13*U12/U13 -> 145616.85 | W12: =W13*V12/V13 -> 145616.85 | X12: =X13*W12/W13 -> 145616.85 | Y12: =Y13*X12/X13 -> 145616.85 | Z12: =Z13*Y12/Y13 -> 167420.09 | AA12: =AA13*Z12/Z13 -> 167420.09 | ... AK12: =AK13*AJ12/AJ13 -> 167420.09
